[2023-11-13T10:01:07.978+0000] {logging_mixin.py:154} INFO - Changing /opt/***/logs/dag_id=simulator_dag_46/run_id=scheduled__2023-11-12T00:00:00+00:00/task_id=setup_and_run_simulator_task_46 permission to 509
[2023-11-13T10:01:08.019+0000] {logging_mixin.py:154} INFO - Failed to change /opt/***/logs/dag_id=simulator_dag_46/run_id=scheduled__2023-11-12T00:00:00+00:00/task_id=setup_and_run_simulator_task_46 permission to 509: [Errno 1] Operation not permitted: '/opt/***/logs/dag_id=simulator_dag_46/run_id=scheduled__2023-11-12T00:00:00+00:00/task_id=setup_and_run_simulator_task_46'
[2023-11-13T10:01:08.411+0000] {logging_mixin.py:154} INFO - Changing /opt/***/logs/dag_id=simulator_dag_46/run_id=scheduled__2023-11-12T00:00:00+00:00/task_id=setup_and_run_simulator_task_46 permission to 509
[2023-11-13T10:01:08.417+0000] {logging_mixin.py:154} INFO - Failed to change /opt/***/logs/dag_id=simulator_dag_46/run_id=scheduled__2023-11-12T00:00:00+00:00/task_id=setup_and_run_simulator_task_46 permission to 509: [Errno 1] Operation not permitted: '/opt/***/logs/dag_id=simulator_dag_46/run_id=scheduled__2023-11-12T00:00:00+00:00/task_id=setup_and_run_simulator_task_46'
[2023-11-13T10:01:08.718+0000] {taskinstance.py:1159} INFO - Dependencies all met for dep_context=non-requeueable deps ti=<TaskInstance: simulator_dag_46.setup_and_run_simulator_task_46 scheduled__2023-11-12T00:00:00+00:00 [queued]>
[2023-11-13T10:01:08.845+0000] {taskinstance.py:1159} INFO - Dependencies all met for dep_context=requeueable deps ti=<TaskInstance: simulator_dag_46.setup_and_run_simulator_task_46 scheduled__2023-11-12T00:00:00+00:00 [queued]>
[2023-11-13T10:01:08.858+0000] {taskinstance.py:1361} INFO - Starting attempt 1 of 3
[2023-11-13T10:01:09.492+0000] {taskinstance.py:1382} INFO - Executing <Task(PythonOperator): setup_and_run_simulator_task_46> on 2023-11-12 00:00:00+00:00
[2023-11-13T10:01:09.590+0000] {standard_task_runner.py:57} INFO - Started process 2869 to run task
[2023-11-13T10:01:09.651+0000] {standard_task_runner.py:84} INFO - Running: ['***', 'tasks', 'run', 'simulator_dag_46', 'setup_and_run_simulator_task_46', 'scheduled__2023-11-12T00:00:00+00:00', '--job-id', '134', '--raw', '--subdir', 'DAGS_FOLDER/timeseries.py', '--cfg-path', '/tmp/tmpk7l99njh']
[2023-11-13T10:01:09.691+0000] {standard_task_runner.py:85} INFO - Job 134: Subtask setup_and_run_simulator_task_46
[2023-11-13T10:01:10.326+0000] {logging_mixin.py:154} INFO - Changing /opt/***/logs/dag_id=simulator_dag_46/run_id=scheduled__2023-11-12T00:00:00+00:00/task_id=setup_and_run_simulator_task_46 permission to 509
[2023-11-13T10:01:10.397+0000] {logging_mixin.py:154} INFO - Failed to change /opt/***/logs/dag_id=simulator_dag_46/run_id=scheduled__2023-11-12T00:00:00+00:00/task_id=setup_and_run_simulator_task_46 permission to 509: [Errno 1] Operation not permitted: '/opt/***/logs/dag_id=simulator_dag_46/run_id=scheduled__2023-11-12T00:00:00+00:00/task_id=setup_and_run_simulator_task_46'
[2023-11-13T10:01:10.511+0000] {task_command.py:416} INFO - Running <TaskInstance: simulator_dag_46.setup_and_run_simulator_task_46 scheduled__2023-11-12T00:00:00+00:00 [running]> on host 84c765240aba
[2023-11-13T10:01:11.607+0000] {taskinstance.py:1662} INFO - Exporting env vars: AIRFLOW_CTX_DAG_OWNER='***' AIRFLOW_CTX_DAG_ID='simulator_dag_46' AIRFLOW_CTX_TASK_ID='setup_and_run_simulator_task_46' AIRFLOW_CTX_EXECUTION_DATE='2023-11-12T00:00:00+00:00' AIRFLOW_CTX_TRY_NUMBER='1' AIRFLOW_CTX_DAG_RUN_ID='scheduled__2023-11-12T00:00:00+00:00'
[2023-11-13T10:01:45.037+0000] {logging_mixin.py:154} INFO - Standard Output: 
[2023-11-13T10:01:45.051+0000] {logging_mixin.py:154} INFO - Standard Error: Traceback (most recent call last):
  File "/djangoapp/Task1/main.py", line 9, in <module>
    from TimeSeriesDirector import TimeSeriesDirector
  File "/djangoapp/Task1/TimeSeriesDirector.py", line 11, in <module>
    from sklearn.preprocessing import MinMaxScaler
  File "/home/***/.local/lib/python3.8/site-packages/sklearn/__init__.py", line 83, in <module>
    from .base import clone
  File "/home/***/.local/lib/python3.8/site-packages/sklearn/base.py", line 19, in <module>
    from .utils import _IS_32BIT
  File "/home/***/.local/lib/python3.8/site-packages/sklearn/utils/__init__.py", line 22, in <module>
    from ._param_validation import Interval, validate_params
  File "/home/***/.local/lib/python3.8/site-packages/sklearn/utils/_param_validation.py", line 15, in <module>
    from .validation import _is_arraylike_not_scalar
  File "/home/***/.local/lib/python3.8/site-packages/sklearn/utils/validation.py", line 25, in <module>
    from ..utils._array_api import _asarray_with_order, _is_numpy_namespace, get_namespace
  File "/home/***/.local/lib/python3.8/site-packages/sklearn/utils/_array_api.py", line 9, in <module>
    from .fixes import parse_version
  File "/home/***/.local/lib/python3.8/site-packages/sklearn/utils/fixes.py", line 19, in <module>
    import scipy.stats
  File "/home/***/.local/lib/python3.8/site-packages/scipy/stats/__init__.py", line 485, in <module>
    from ._stats_py import *
  File "/home/***/.local/lib/python3.8/site-packages/scipy/stats/_stats_py.py", line 53, in <module>
    from ._hypotests import _all_partitions
  File "/home/***/.local/lib/python3.8/site-packages/scipy/stats/_hypotests.py", line 13, in <module>
    from scipy.fft import ifft
  File "/home/***/.local/lib/python3.8/site-packages/scipy/fft/__init__.py", line 85, in <module>
    from ._basic import (
  File "/home/***/.local/lib/python3.8/site-packages/scipy/fft/_basic.py", line 1, in <module>
    from scipy._lib.uarray import generate_multimethod, Dispatchable
  File "/home/***/.local/lib/python3.8/site-packages/scipy/_lib/uarray.py", line 13, in <module>
    import uarray as _uarray
  File "<frozen importlib._bootstrap>", line 991, in _find_and_load
  File "<frozen importlib._bootstrap>", line 971, in _find_and_load_unlocked
  File "<frozen importlib._bootstrap>", line 914, in _find_spec
  File "<frozen importlib._bootstrap_external>", line 1407, in find_spec
  File "<frozen importlib._bootstrap_external>", line 1379, in _get_spec
  File "<frozen importlib._bootstrap_external>", line 1510, in find_spec
  File "<frozen importlib._bootstrap_external>", line 1553, in _fill_cache
OSError: [Errno 12] Cannot allocate memory: '/djangoapp/Task1'
[2023-11-13T10:01:45.060+0000] {logging_mixin.py:154} INFO - this is my stattututututs 1
[2023-11-13T10:01:45.125+0000] {logging_mixin.py:154} INFO - this is hiiiim <Thread(Thread-1, initial)>
[2023-11-13T10:01:45.155+0000] {python.py:194} INFO - Done. Returned value was: None
[2023-11-13T10:01:45.311+0000] {taskinstance.py:1400} INFO - Marking task as SUCCESS. dag_id=simulator_dag_46, task_id=setup_and_run_simulator_task_46, execution_date=20231112T000000, start_date=20231113T100108, end_date=20231113T100145
[2023-11-13T10:01:50.522+0000] {local_task_job_runner.py:228} INFO - Task exited with return code 0
[2023-11-13T10:01:50.856+0000] {taskinstance.py:2778} INFO - 0 downstream tasks scheduled from follow-on schedule check
