[2023-11-13T10:01:01.548+0000] {logging_mixin.py:154} INFO - Changing /opt/***/logs/dag_id=simulator_dag_45/run_id=scheduled__2023-11-12T00:00:00+00:00/task_id=setup_and_run_simulator_task_45 permission to 509
[2023-11-13T10:01:01.564+0000] {logging_mixin.py:154} INFO - Failed to change /opt/***/logs/dag_id=simulator_dag_45/run_id=scheduled__2023-11-12T00:00:00+00:00/task_id=setup_and_run_simulator_task_45 permission to 509: [Errno 1] Operation not permitted: '/opt/***/logs/dag_id=simulator_dag_45/run_id=scheduled__2023-11-12T00:00:00+00:00/task_id=setup_and_run_simulator_task_45'
[2023-11-13T10:01:01.945+0000] {logging_mixin.py:154} INFO - Changing /opt/***/logs/dag_id=simulator_dag_45/run_id=scheduled__2023-11-12T00:00:00+00:00/task_id=setup_and_run_simulator_task_45 permission to 509
[2023-11-13T10:01:01.957+0000] {logging_mixin.py:154} INFO - Failed to change /opt/***/logs/dag_id=simulator_dag_45/run_id=scheduled__2023-11-12T00:00:00+00:00/task_id=setup_and_run_simulator_task_45 permission to 509: [Errno 1] Operation not permitted: '/opt/***/logs/dag_id=simulator_dag_45/run_id=scheduled__2023-11-12T00:00:00+00:00/task_id=setup_and_run_simulator_task_45'
[2023-11-13T10:01:02.307+0000] {taskinstance.py:1159} INFO - Dependencies all met for dep_context=non-requeueable deps ti=<TaskInstance: simulator_dag_45.setup_and_run_simulator_task_45 scheduled__2023-11-12T00:00:00+00:00 [queued]>
[2023-11-13T10:01:02.397+0000] {taskinstance.py:1159} INFO - Dependencies all met for dep_context=requeueable deps ti=<TaskInstance: simulator_dag_45.setup_and_run_simulator_task_45 scheduled__2023-11-12T00:00:00+00:00 [queued]>
[2023-11-13T10:01:02.424+0000] {taskinstance.py:1361} INFO - Starting attempt 1 of 3
[2023-11-13T10:01:03.463+0000] {taskinstance.py:1382} INFO - Executing <Task(PythonOperator): setup_and_run_simulator_task_45> on 2023-11-12 00:00:00+00:00
[2023-11-13T10:01:03.526+0000] {standard_task_runner.py:57} INFO - Started process 2834 to run task
[2023-11-13T10:01:03.627+0000] {standard_task_runner.py:84} INFO - Running: ['***', 'tasks', 'run', 'simulator_dag_45', 'setup_and_run_simulator_task_45', 'scheduled__2023-11-12T00:00:00+00:00', '--job-id', '128', '--raw', '--subdir', 'DAGS_FOLDER/timeseries.py', '--cfg-path', '/tmp/tmp_di8dsbl']
[2023-11-13T10:01:03.808+0000] {standard_task_runner.py:85} INFO - Job 128: Subtask setup_and_run_simulator_task_45
[2023-11-13T10:01:04.653+0000] {logging_mixin.py:154} INFO - Changing /opt/***/logs/dag_id=simulator_dag_45/run_id=scheduled__2023-11-12T00:00:00+00:00/task_id=setup_and_run_simulator_task_45 permission to 509
[2023-11-13T10:01:04.671+0000] {logging_mixin.py:154} INFO - Failed to change /opt/***/logs/dag_id=simulator_dag_45/run_id=scheduled__2023-11-12T00:00:00+00:00/task_id=setup_and_run_simulator_task_45 permission to 509: [Errno 1] Operation not permitted: '/opt/***/logs/dag_id=simulator_dag_45/run_id=scheduled__2023-11-12T00:00:00+00:00/task_id=setup_and_run_simulator_task_45'
[2023-11-13T10:01:04.717+0000] {task_command.py:416} INFO - Running <TaskInstance: simulator_dag_45.setup_and_run_simulator_task_45 scheduled__2023-11-12T00:00:00+00:00 [running]> on host 84c765240aba
[2023-11-13T10:01:06.512+0000] {taskinstance.py:1662} INFO - Exporting env vars: AIRFLOW_CTX_DAG_OWNER='***' AIRFLOW_CTX_DAG_ID='simulator_dag_45' AIRFLOW_CTX_TASK_ID='setup_and_run_simulator_task_45' AIRFLOW_CTX_EXECUTION_DATE='2023-11-12T00:00:00+00:00' AIRFLOW_CTX_TRY_NUMBER='1' AIRFLOW_CTX_DAG_RUN_ID='scheduled__2023-11-12T00:00:00+00:00'
[2023-11-13T10:01:45.285+0000] {logging_mixin.py:154} INFO - Standard Output: File 'TimeSeries_daily_exist_weekly_exist_noise_small_trend_exist_cycle_exist_outliers_5%_freq_1H_missing_6%.csv' generated.
[2023-11-13T10:01:45.300+0000] {logging_mixin.py:154} INFO - Standard Error: Traceback (most recent call last):
  File "/djangoapp/Task1/main.py", line 74, in <module>
    main()
  File "/djangoapp/Task1/main.py", line 69, in main
    director.generate_multiple_datasets(config_attributes,data_saving)
  File "/djangoapp/Task1/TimeSeriesDirector.py", line 130, in generate_multiple_datasets
    data_saver.save_file(time_series_data, i, config)
  File "/djangoapp/Task1/FolderSaver.py", line 41, in save_file
    df = df.to_csv(config_file_path + str(counter + 1) + '.csv', encoding='utf-8', index=False)
  File "/home/***/.local/lib/python3.8/site-packages/pandas/core/generic.py", line 3772, in to_csv
    return DataFrameRenderer(formatter).to_csv(
  File "/home/***/.local/lib/python3.8/site-packages/pandas/io/formats/format.py", line 1186, in to_csv
    csv_formatter.save()
  File "/home/***/.local/lib/python3.8/site-packages/pandas/io/formats/csvs.py", line 240, in save
    with get_handle(
  File "/home/***/.local/lib/python3.8/site-packages/pandas/io/common.py", line 707, in get_handle
    if _is_binary_mode(path_or_buf, mode) and "b" not in mode:
  File "/home/***/.local/lib/python3.8/site-packages/pandas/io/common.py", line 1167, in _is_binary_mode
    return isinstance(handle, _get_binary_io_classes()) or "b" in getattr(
  File "/home/***/.local/lib/python3.8/site-packages/pandas/io/common.py", line 1182, in _get_binary_io_classes
    zstd = import_optional_dependency("zstandard", errors="ignore")
  File "/home/***/.local/lib/python3.8/site-packages/pandas/compat/_optional.py", line 142, in import_optional_dependency
    module = importlib.import_module(name)
  File "/usr/local/lib/python3.8/importlib/__init__.py", line 127, in import_module
    return _bootstrap._gcd_import(name[level:], package, level)
  File "<frozen importlib._bootstrap>", line 1014, in _gcd_import
  File "<frozen importlib._bootstrap>", line 991, in _find_and_load
  File "<frozen importlib._bootstrap>", line 971, in _find_and_load_unlocked
  File "<frozen importlib._bootstrap>", line 914, in _find_spec
  File "<frozen importlib._bootstrap_external>", line 1407, in find_spec
  File "<frozen importlib._bootstrap_external>", line 1379, in _get_spec
  File "<frozen importlib._bootstrap_external>", line 1510, in find_spec
  File "<frozen importlib._bootstrap_external>", line 1553, in _fill_cache
OSError: [Errno 12] Cannot allocate memory: '/djangoapp/Task1'
[2023-11-13T10:01:45.317+0000] {logging_mixin.py:154} INFO - this is my stattututututs 1
[2023-11-13T10:01:45.375+0000] {logging_mixin.py:154} INFO - this is hiiiim <Thread(Thread-1, initial)>
[2023-11-13T10:01:45.460+0000] {python.py:194} INFO - Done. Returned value was: None
[2023-11-13T10:01:45.722+0000] {taskinstance.py:1400} INFO - Marking task as SUCCESS. dag_id=simulator_dag_45, task_id=setup_and_run_simulator_task_45, execution_date=20231112T000000, start_date=20231113T100102, end_date=20231113T100145
[2023-11-13T10:01:50.618+0000] {local_task_job_runner.py:228} INFO - Task exited with return code 0
[2023-11-13T10:01:50.796+0000] {taskinstance.py:2778} INFO - 0 downstream tasks scheduled from follow-on schedule check
