[2023-11-12T21:40:57.862+0000] {logging_mixin.py:154} INFO - Changing /opt/***/logs/dag_id=simulator_dag_22/run_id=scheduled__2023-11-11T00:00:00+00:00/task_id=setup_and_run_simulator_task_22 permission to 509
[2023-11-12T21:40:57.863+0000] {logging_mixin.py:154} INFO - Failed to change /opt/***/logs/dag_id=simulator_dag_22/run_id=scheduled__2023-11-11T00:00:00+00:00/task_id=setup_and_run_simulator_task_22 permission to 509: [Errno 1] Operation not permitted: '/opt/***/logs/dag_id=simulator_dag_22/run_id=scheduled__2023-11-11T00:00:00+00:00/task_id=setup_and_run_simulator_task_22'
[2023-11-12T21:40:57.905+0000] {logging_mixin.py:154} INFO - Changing /opt/***/logs/dag_id=simulator_dag_22/run_id=scheduled__2023-11-11T00:00:00+00:00/task_id=setup_and_run_simulator_task_22 permission to 509
[2023-11-12T21:40:57.907+0000] {logging_mixin.py:154} INFO - Failed to change /opt/***/logs/dag_id=simulator_dag_22/run_id=scheduled__2023-11-11T00:00:00+00:00/task_id=setup_and_run_simulator_task_22 permission to 509: [Errno 1] Operation not permitted: '/opt/***/logs/dag_id=simulator_dag_22/run_id=scheduled__2023-11-11T00:00:00+00:00/task_id=setup_and_run_simulator_task_22'
[2023-11-12T21:40:57.949+0000] {taskinstance.py:1159} INFO - Dependencies all met for dep_context=non-requeueable deps ti=<TaskInstance: simulator_dag_22.setup_and_run_simulator_task_22 scheduled__2023-11-11T00:00:00+00:00 [queued]>
[2023-11-12T21:40:57.963+0000] {taskinstance.py:1159} INFO - Dependencies all met for dep_context=requeueable deps ti=<TaskInstance: simulator_dag_22.setup_and_run_simulator_task_22 scheduled__2023-11-11T00:00:00+00:00 [queued]>
[2023-11-12T21:40:57.964+0000] {taskinstance.py:1361} INFO - Starting attempt 1 of 3
[2023-11-12T21:40:57.983+0000] {taskinstance.py:1382} INFO - Executing <Task(PythonOperator): setup_and_run_simulator_task_22> on 2023-11-11 00:00:00+00:00
[2023-11-12T21:40:57.991+0000] {standard_task_runner.py:57} INFO - Started process 715 to run task
[2023-11-12T21:40:57.996+0000] {standard_task_runner.py:84} INFO - Running: ['***', 'tasks', 'run', 'simulator_dag_22', 'setup_and_run_simulator_task_22', 'scheduled__2023-11-11T00:00:00+00:00', '--job-id', '49', '--raw', '--subdir', 'DAGS_FOLDER/timeseries.py', '--cfg-path', '/tmp/tmpj3e4mmtu']
[2023-11-12T21:40:58.002+0000] {standard_task_runner.py:85} INFO - Job 49: Subtask setup_and_run_simulator_task_22
[2023-11-12T21:40:58.071+0000] {logging_mixin.py:154} INFO - Changing /opt/***/logs/dag_id=simulator_dag_22/run_id=scheduled__2023-11-11T00:00:00+00:00/task_id=setup_and_run_simulator_task_22 permission to 509
[2023-11-12T21:40:58.072+0000] {logging_mixin.py:154} INFO - Failed to change /opt/***/logs/dag_id=simulator_dag_22/run_id=scheduled__2023-11-11T00:00:00+00:00/task_id=setup_and_run_simulator_task_22 permission to 509: [Errno 1] Operation not permitted: '/opt/***/logs/dag_id=simulator_dag_22/run_id=scheduled__2023-11-11T00:00:00+00:00/task_id=setup_and_run_simulator_task_22'
[2023-11-12T21:40:58.079+0000] {task_command.py:416} INFO - Running <TaskInstance: simulator_dag_22.setup_and_run_simulator_task_22 scheduled__2023-11-11T00:00:00+00:00 [running]> on host 84c765240aba
[2023-11-12T21:40:58.166+0000] {taskinstance.py:1662} INFO - Exporting env vars: AIRFLOW_CTX_DAG_OWNER='***' AIRFLOW_CTX_DAG_ID='simulator_dag_22' AIRFLOW_CTX_TASK_ID='setup_and_run_simulator_task_22' AIRFLOW_CTX_EXECUTION_DATE='2023-11-11T00:00:00+00:00' AIRFLOW_CTX_TRY_NUMBER='1' AIRFLOW_CTX_DAG_RUN_ID='scheduled__2023-11-11T00:00:00+00:00'
[2023-11-12T21:40:58.174+0000] {taskinstance.py:1937} ERROR - Task failed with exception
Traceback (most recent call last):
  File "/home/airflow/.local/lib/python3.8/site-packages/urllib3/connection.py", line 174, in _new_conn
    conn = connection.create_connection(
  File "/home/airflow/.local/lib/python3.8/site-packages/urllib3/util/connection.py", line 95, in create_connection
    raise err
  File "/home/airflow/.local/lib/python3.8/site-packages/urllib3/util/connection.py", line 85, in create_connection
    sock.connect(sa)
ConnectionRefusedError: [Errno 111] Connection refused

During handling of the above exception, another exception occurred:

Traceback (most recent call last):
  File "/home/airflow/.local/lib/python3.8/site-packages/urllib3/connectionpool.py", line 715, in urlopen
    httplib_response = self._make_request(
  File "/home/airflow/.local/lib/python3.8/site-packages/urllib3/connectionpool.py", line 416, in _make_request
    conn.request(method, url, **httplib_request_kw)
  File "/home/airflow/.local/lib/python3.8/site-packages/urllib3/connection.py", line 244, in request
    super(HTTPConnection, self).request(method, url, body=body, headers=headers)
  File "/usr/local/lib/python3.8/http/client.py", line 1256, in request
    self._send_request(method, url, body, headers, encode_chunked)
  File "/usr/local/lib/python3.8/http/client.py", line 1302, in _send_request
    self.endheaders(body, encode_chunked=encode_chunked)
  File "/usr/local/lib/python3.8/http/client.py", line 1251, in endheaders
    self._send_output(message_body, encode_chunked=encode_chunked)
  File "/usr/local/lib/python3.8/http/client.py", line 1011, in _send_output
    self.send(msg)
  File "/usr/local/lib/python3.8/http/client.py", line 951, in send
    self.connect()
  File "/home/airflow/.local/lib/python3.8/site-packages/urllib3/connection.py", line 205, in connect
    conn = self._new_conn()
  File "/home/airflow/.local/lib/python3.8/site-packages/urllib3/connection.py", line 186, in _new_conn
    raise NewConnectionError(
urllib3.exceptions.NewConnectionError: <urllib3.connection.HTTPConnection object at 0x7f74257d17c0>: Failed to establish a new connection: [Errno 111] Connection refused

During handling of the above exception, another exception occurred:

Traceback (most recent call last):
  File "/home/airflow/.local/lib/python3.8/site-packages/requests/adapters.py", line 486, in send
    resp = conn.urlopen(
  File "/home/airflow/.local/lib/python3.8/site-packages/urllib3/connectionpool.py", line 799, in urlopen
    retries = retries.increment(
  File "/home/airflow/.local/lib/python3.8/site-packages/urllib3/util/retry.py", line 592, in increment
    raise MaxRetryError(_pool, url, error or ResponseError(cause))
urllib3.exceptions.MaxRetryError: HTTPConnectionPool(host='localhost', port=8085): Max retries exceeded with url: /run_simulator22/ (Caused by NewConnectionError('<urllib3.connection.HTTPConnection object at 0x7f74257d17c0>: Failed to establish a new connection: [Errno 111] Connection refused'))

During handling of the above exception, another exception occurred:

Traceback (most recent call last):
  File "/home/airflow/.local/lib/python3.8/site-packages/airflow/operators/python.py", line 192, in execute
    return_value = self.execute_callable()
  File "/home/airflow/.local/lib/python3.8/site-packages/airflow/operators/python.py", line 209, in execute_callable
    return self.python_callable(*self.op_args, **self.op_kwargs)
  File "/opt/airflow/dags/timeseries.py", line 54, in setup_and_run_simulator
    trigger_run_simulator(simulator_data_dict, **kwargs)
  File "/opt/airflow/dags/timeseries.py", line 61, in trigger_run_simulator
    response = requests.post(f"{django_app_url}{endpoint_url}{simulator_id}/")
  File "/home/airflow/.local/lib/python3.8/site-packages/requests/api.py", line 115, in post
    return request("post", url, data=data, json=json, **kwargs)
  File "/home/airflow/.local/lib/python3.8/site-packages/requests/api.py", line 59, in request
    return session.request(method=method, url=url, **kwargs)
  File "/home/airflow/.local/lib/python3.8/site-packages/requests/sessions.py", line 589, in request
    resp = self.send(prep, **send_kwargs)
  File "/home/airflow/.local/lib/python3.8/site-packages/requests/sessions.py", line 703, in send
    r = adapter.send(request, **kwargs)
  File "/home/airflow/.local/lib/python3.8/site-packages/requests/adapters.py", line 519, in send
    raise ConnectionError(e, request=request)
requests.exceptions.ConnectionError: HTTPConnectionPool(host='localhost', port=8085): Max retries exceeded with url: /run_simulator22/ (Caused by NewConnectionError('<urllib3.connection.HTTPConnection object at 0x7f74257d17c0>: Failed to establish a new connection: [Errno 111] Connection refused'))
[2023-11-12T21:40:58.195+0000] {taskinstance.py:1400} INFO - Marking task as UP_FOR_RETRY. dag_id=simulator_dag_22, task_id=setup_and_run_simulator_task_22, execution_date=20231111T000000, start_date=20231112T214057, end_date=20231112T214058
[2023-11-12T21:40:58.214+0000] {standard_task_runner.py:104} ERROR - Failed to execute job 49 for task setup_and_run_simulator_task_22 (HTTPConnectionPool(host='localhost', port=8085): Max retries exceeded with url: /run_simulator22/ (Caused by NewConnectionError('<urllib3.connection.HTTPConnection object at 0x7f74257d17c0>: Failed to establish a new connection: [Errno 111] Connection refused')); 715)
[2023-11-12T21:40:58.232+0000] {local_task_job_runner.py:228} INFO - Task exited with return code 1
[2023-11-12T21:40:58.250+0000] {taskinstance.py:2778} INFO - 0 downstream tasks scheduled from follow-on schedule check
