[2023-11-12T13:47:33.176+0000] {logging_mixin.py:154} INFO - Changing /opt/***/logs/dag_id=simulator_dag_1/run_id=scheduled__2023-11-11T00:00:00+00:00/task_id=setup_and_run_simulator_task_1 permission to 509
[2023-11-12T13:47:33.180+0000] {logging_mixin.py:154} INFO - Failed to change /opt/***/logs/dag_id=simulator_dag_1/run_id=scheduled__2023-11-11T00:00:00+00:00/task_id=setup_and_run_simulator_task_1 permission to 509: [Errno 1] Operation not permitted: '/opt/***/logs/dag_id=simulator_dag_1/run_id=scheduled__2023-11-11T00:00:00+00:00/task_id=setup_and_run_simulator_task_1'
[2023-11-12T13:47:33.245+0000] {logging_mixin.py:154} INFO - Changing /opt/***/logs/dag_id=simulator_dag_1/run_id=scheduled__2023-11-11T00:00:00+00:00/task_id=setup_and_run_simulator_task_1 permission to 509
[2023-11-12T13:47:33.248+0000] {logging_mixin.py:154} INFO - Failed to change /opt/***/logs/dag_id=simulator_dag_1/run_id=scheduled__2023-11-11T00:00:00+00:00/task_id=setup_and_run_simulator_task_1 permission to 509: [Errno 1] Operation not permitted: '/opt/***/logs/dag_id=simulator_dag_1/run_id=scheduled__2023-11-11T00:00:00+00:00/task_id=setup_and_run_simulator_task_1'
[2023-11-12T13:47:33.304+0000] {taskinstance.py:1159} INFO - Dependencies all met for dep_context=non-requeueable deps ti=<TaskInstance: simulator_dag_1.setup_and_run_simulator_task_1 scheduled__2023-11-11T00:00:00+00:00 [queued]>
[2023-11-12T13:47:33.317+0000] {taskinstance.py:1159} INFO - Dependencies all met for dep_context=requeueable deps ti=<TaskInstance: simulator_dag_1.setup_and_run_simulator_task_1 scheduled__2023-11-11T00:00:00+00:00 [queued]>
[2023-11-12T13:47:33.319+0000] {taskinstance.py:1361} INFO - Starting attempt 1 of 1
[2023-11-12T13:47:33.344+0000] {taskinstance.py:1382} INFO - Executing <Task(PythonOperator): setup_and_run_simulator_task_1> on 2023-11-11 00:00:00+00:00
[2023-11-12T13:47:33.352+0000] {standard_task_runner.py:57} INFO - Started process 702 to run task
[2023-11-12T13:47:33.358+0000] {standard_task_runner.py:84} INFO - Running: ['***', 'tasks', 'run', 'simulator_dag_1', 'setup_and_run_simulator_task_1', 'scheduled__2023-11-11T00:00:00+00:00', '--job-id', '35', '--raw', '--subdir', 'DAGS_FOLDER/timeseries.py', '--cfg-path', '/tmp/tmplzjl1e8o']
[2023-11-12T13:47:33.363+0000] {standard_task_runner.py:85} INFO - Job 35: Subtask setup_and_run_simulator_task_1
[2023-11-12T13:47:33.441+0000] {logging_mixin.py:154} INFO - Changing /opt/***/logs/dag_id=simulator_dag_1/run_id=scheduled__2023-11-11T00:00:00+00:00/task_id=setup_and_run_simulator_task_1 permission to 509
[2023-11-12T13:47:33.443+0000] {logging_mixin.py:154} INFO - Failed to change /opt/***/logs/dag_id=simulator_dag_1/run_id=scheduled__2023-11-11T00:00:00+00:00/task_id=setup_and_run_simulator_task_1 permission to 509: [Errno 1] Operation not permitted: '/opt/***/logs/dag_id=simulator_dag_1/run_id=scheduled__2023-11-11T00:00:00+00:00/task_id=setup_and_run_simulator_task_1'
[2023-11-12T13:47:33.449+0000] {task_command.py:416} INFO - Running <TaskInstance: simulator_dag_1.setup_and_run_simulator_task_1 scheduled__2023-11-11T00:00:00+00:00 [running]> on host 4bc8bf47bb6b
[2023-11-12T13:47:33.598+0000] {taskinstance.py:1662} INFO - Exporting env vars: AIRFLOW_CTX_DAG_OWNER='***' AIRFLOW_CTX_DAG_ID='simulator_dag_1' AIRFLOW_CTX_TASK_ID='setup_and_run_simulator_task_1' AIRFLOW_CTX_EXECUTION_DATE='2023-11-11T00:00:00+00:00' AIRFLOW_CTX_TRY_NUMBER='1' AIRFLOW_CTX_DAG_RUN_ID='scheduled__2023-11-11T00:00:00+00:00'
[2023-11-12T13:47:33.617+0000] {taskinstance.py:1937} ERROR - Task failed with exception
Traceback (most recent call last):
  File "/home/airflow/.local/lib/python3.8/site-packages/urllib3/connection.py", line 174, in _new_conn
    conn = connection.create_connection(
  File "/home/airflow/.local/lib/python3.8/site-packages/urllib3/util/connection.py", line 95, in create_connection
    raise err
  File "/home/airflow/.local/lib/python3.8/site-packages/urllib3/util/connection.py", line 85, in create_connection
    sock.connect(sa)
ConnectionRefusedError: [Errno 111] Connection refused

During handling of the above exception, another exception occurred:

Traceback (most recent call last):
  File "/home/airflow/.local/lib/python3.8/site-packages/urllib3/connectionpool.py", line 715, in urlopen
    httplib_response = self._make_request(
  File "/home/airflow/.local/lib/python3.8/site-packages/urllib3/connectionpool.py", line 416, in _make_request
    conn.request(method, url, **httplib_request_kw)
  File "/home/airflow/.local/lib/python3.8/site-packages/urllib3/connection.py", line 244, in request
    super(HTTPConnection, self).request(method, url, body=body, headers=headers)
  File "/usr/local/lib/python3.8/http/client.py", line 1256, in request
    self._send_request(method, url, body, headers, encode_chunked)
  File "/usr/local/lib/python3.8/http/client.py", line 1302, in _send_request
    self.endheaders(body, encode_chunked=encode_chunked)
  File "/usr/local/lib/python3.8/http/client.py", line 1251, in endheaders
    self._send_output(message_body, encode_chunked=encode_chunked)
  File "/usr/local/lib/python3.8/http/client.py", line 1011, in _send_output
    self.send(msg)
  File "/usr/local/lib/python3.8/http/client.py", line 951, in send
    self.connect()
  File "/home/airflow/.local/lib/python3.8/site-packages/urllib3/connection.py", line 205, in connect
    conn = self._new_conn()
  File "/home/airflow/.local/lib/python3.8/site-packages/urllib3/connection.py", line 186, in _new_conn
    raise NewConnectionError(
urllib3.exceptions.NewConnectionError: <urllib3.connection.HTTPConnection object at 0x7f75924e6cd0>: Failed to establish a new connection: [Errno 111] Connection refused

During handling of the above exception, another exception occurred:

Traceback (most recent call last):
  File "/home/airflow/.local/lib/python3.8/site-packages/requests/adapters.py", line 486, in send
    resp = conn.urlopen(
  File "/home/airflow/.local/lib/python3.8/site-packages/urllib3/connectionpool.py", line 799, in urlopen
    retries = retries.increment(
  File "/home/airflow/.local/lib/python3.8/site-packages/urllib3/util/retry.py", line 592, in increment
    raise MaxRetryError(_pool, url, error or ResponseError(cause))
urllib3.exceptions.MaxRetryError: HTTPConnectionPool(host='localhost', port=8085): Max retries exceeded with url: /run_simulator/ (Caused by NewConnectionError('<urllib3.connection.HTTPConnection object at 0x7f75924e6cd0>: Failed to establish a new connection: [Errno 111] Connection refused'))

During handling of the above exception, another exception occurred:

Traceback (most recent call last):
  File "/home/airflow/.local/lib/python3.8/site-packages/airflow/operators/python.py", line 192, in execute
    return_value = self.execute_callable()
  File "/home/airflow/.local/lib/python3.8/site-packages/airflow/operators/python.py", line 209, in execute_callable
    return self.python_callable(*self.op_args, **self.op_kwargs)
  File "/opt/airflow/dags/timeseries.py", line 51, in setup_and_run_simulator
    trigger_run_simulator(simulator_data_dict, **kwargs)
  File "/opt/airflow/dags/timeseries.py", line 61, in trigger_run_simulator
    response = requests.post(api_endpoint, json={"id": simulator_data_dict["id"]})
  File "/home/airflow/.local/lib/python3.8/site-packages/requests/api.py", line 115, in post
    return request("post", url, data=data, json=json, **kwargs)
  File "/home/airflow/.local/lib/python3.8/site-packages/requests/api.py", line 59, in request
    return session.request(method=method, url=url, **kwargs)
  File "/home/airflow/.local/lib/python3.8/site-packages/requests/sessions.py", line 589, in request
    resp = self.send(prep, **send_kwargs)
  File "/home/airflow/.local/lib/python3.8/site-packages/requests/sessions.py", line 703, in send
    r = adapter.send(request, **kwargs)
  File "/home/airflow/.local/lib/python3.8/site-packages/requests/adapters.py", line 519, in send
    raise ConnectionError(e, request=request)
requests.exceptions.ConnectionError: HTTPConnectionPool(host='localhost', port=8085): Max retries exceeded with url: /run_simulator/ (Caused by NewConnectionError('<urllib3.connection.HTTPConnection object at 0x7f75924e6cd0>: Failed to establish a new connection: [Errno 111] Connection refused'))
[2023-11-12T13:47:33.654+0000] {taskinstance.py:1400} INFO - Marking task as FAILED. dag_id=simulator_dag_1, task_id=setup_and_run_simulator_task_1, execution_date=20231111T000000, start_date=20231112T134733, end_date=20231112T134733
[2023-11-12T13:47:33.682+0000] {standard_task_runner.py:104} ERROR - Failed to execute job 35 for task setup_and_run_simulator_task_1 (HTTPConnectionPool(host='localhost', port=8085): Max retries exceeded with url: /run_simulator/ (Caused by NewConnectionError('<urllib3.connection.HTTPConnection object at 0x7f75924e6cd0>: Failed to establish a new connection: [Errno 111] Connection refused')); 702)
[2023-11-12T13:47:33.744+0000] {local_task_job_runner.py:228} INFO - Task exited with return code 1
[2023-11-12T13:47:33.781+0000] {taskinstance.py:2778} INFO - 0 downstream tasks scheduled from follow-on schedule check
[2023-11-12T14:01:36.960+0000] {logging_mixin.py:154} INFO - Changing /opt/***/logs/dag_id=simulator_dag_1/run_id=scheduled__2023-11-11T00:00:00+00:00/task_id=setup_and_run_simulator_task_1 permission to 509
[2023-11-12T14:01:36.963+0000] {logging_mixin.py:154} INFO - Failed to change /opt/***/logs/dag_id=simulator_dag_1/run_id=scheduled__2023-11-11T00:00:00+00:00/task_id=setup_and_run_simulator_task_1 permission to 509: [Errno 1] Operation not permitted: '/opt/***/logs/dag_id=simulator_dag_1/run_id=scheduled__2023-11-11T00:00:00+00:00/task_id=setup_and_run_simulator_task_1'
[2023-11-12T14:01:37.015+0000] {logging_mixin.py:154} INFO - Changing /opt/***/logs/dag_id=simulator_dag_1/run_id=scheduled__2023-11-11T00:00:00+00:00/task_id=setup_and_run_simulator_task_1 permission to 509
[2023-11-12T14:01:37.017+0000] {logging_mixin.py:154} INFO - Failed to change /opt/***/logs/dag_id=simulator_dag_1/run_id=scheduled__2023-11-11T00:00:00+00:00/task_id=setup_and_run_simulator_task_1 permission to 509: [Errno 1] Operation not permitted: '/opt/***/logs/dag_id=simulator_dag_1/run_id=scheduled__2023-11-11T00:00:00+00:00/task_id=setup_and_run_simulator_task_1'
[2023-11-12T14:01:37.102+0000] {taskinstance.py:1159} INFO - Dependencies all met for dep_context=non-requeueable deps ti=<TaskInstance: simulator_dag_1.setup_and_run_simulator_task_1 scheduled__2023-11-11T00:00:00+00:00 [queued]>
[2023-11-12T14:01:37.128+0000] {taskinstance.py:1159} INFO - Dependencies all met for dep_context=requeueable deps ti=<TaskInstance: simulator_dag_1.setup_and_run_simulator_task_1 scheduled__2023-11-11T00:00:00+00:00 [queued]>
[2023-11-12T14:01:37.131+0000] {taskinstance.py:1361} INFO - Starting attempt 1 of 1
[2023-11-12T14:01:37.171+0000] {taskinstance.py:1382} INFO - Executing <Task(PythonOperator): setup_and_run_simulator_task_1> on 2023-11-11 00:00:00+00:00
[2023-11-12T14:01:37.186+0000] {standard_task_runner.py:57} INFO - Started process 907 to run task
[2023-11-12T14:01:37.195+0000] {standard_task_runner.py:84} INFO - Running: ['***', 'tasks', 'run', 'simulator_dag_1', 'setup_and_run_simulator_task_1', 'scheduled__2023-11-11T00:00:00+00:00', '--job-id', '37', '--raw', '--subdir', 'DAGS_FOLDER/timeseries.py', '--cfg-path', '/tmp/tmpyzv_811a']
[2023-11-12T14:01:37.204+0000] {standard_task_runner.py:85} INFO - Job 37: Subtask setup_and_run_simulator_task_1
[2023-11-12T14:01:37.322+0000] {logging_mixin.py:154} INFO - Changing /opt/***/logs/dag_id=simulator_dag_1/run_id=scheduled__2023-11-11T00:00:00+00:00/task_id=setup_and_run_simulator_task_1 permission to 509
[2023-11-12T14:01:37.325+0000] {logging_mixin.py:154} INFO - Failed to change /opt/***/logs/dag_id=simulator_dag_1/run_id=scheduled__2023-11-11T00:00:00+00:00/task_id=setup_and_run_simulator_task_1 permission to 509: [Errno 1] Operation not permitted: '/opt/***/logs/dag_id=simulator_dag_1/run_id=scheduled__2023-11-11T00:00:00+00:00/task_id=setup_and_run_simulator_task_1'
[2023-11-12T14:01:37.345+0000] {task_command.py:416} INFO - Running <TaskInstance: simulator_dag_1.setup_and_run_simulator_task_1 scheduled__2023-11-11T00:00:00+00:00 [running]> on host 4bc8bf47bb6b
[2023-11-12T14:01:37.502+0000] {taskinstance.py:1662} INFO - Exporting env vars: AIRFLOW_CTX_DAG_OWNER='***' AIRFLOW_CTX_DAG_ID='simulator_dag_1' AIRFLOW_CTX_TASK_ID='setup_and_run_simulator_task_1' AIRFLOW_CTX_EXECUTION_DATE='2023-11-11T00:00:00+00:00' AIRFLOW_CTX_TRY_NUMBER='1' AIRFLOW_CTX_DAG_RUN_ID='scheduled__2023-11-11T00:00:00+00:00'
[2023-11-12T14:01:37.518+0000] {taskinstance.py:1937} ERROR - Task failed with exception
Traceback (most recent call last):
  File "/home/airflow/.local/lib/python3.8/site-packages/urllib3/connection.py", line 174, in _new_conn
    conn = connection.create_connection(
  File "/home/airflow/.local/lib/python3.8/site-packages/urllib3/util/connection.py", line 95, in create_connection
    raise err
  File "/home/airflow/.local/lib/python3.8/site-packages/urllib3/util/connection.py", line 85, in create_connection
    sock.connect(sa)
ConnectionRefusedError: [Errno 111] Connection refused

During handling of the above exception, another exception occurred:

Traceback (most recent call last):
  File "/home/airflow/.local/lib/python3.8/site-packages/urllib3/connectionpool.py", line 715, in urlopen
    httplib_response = self._make_request(
  File "/home/airflow/.local/lib/python3.8/site-packages/urllib3/connectionpool.py", line 416, in _make_request
    conn.request(method, url, **httplib_request_kw)
  File "/home/airflow/.local/lib/python3.8/site-packages/urllib3/connection.py", line 244, in request
    super(HTTPConnection, self).request(method, url, body=body, headers=headers)
  File "/usr/local/lib/python3.8/http/client.py", line 1256, in request
    self._send_request(method, url, body, headers, encode_chunked)
  File "/usr/local/lib/python3.8/http/client.py", line 1302, in _send_request
    self.endheaders(body, encode_chunked=encode_chunked)
  File "/usr/local/lib/python3.8/http/client.py", line 1251, in endheaders
    self._send_output(message_body, encode_chunked=encode_chunked)
  File "/usr/local/lib/python3.8/http/client.py", line 1011, in _send_output
    self.send(msg)
  File "/usr/local/lib/python3.8/http/client.py", line 951, in send
    self.connect()
  File "/home/airflow/.local/lib/python3.8/site-packages/urllib3/connection.py", line 205, in connect
    conn = self._new_conn()
  File "/home/airflow/.local/lib/python3.8/site-packages/urllib3/connection.py", line 186, in _new_conn
    raise NewConnectionError(
urllib3.exceptions.NewConnectionError: <urllib3.connection.HTTPConnection object at 0x7f7592721e50>: Failed to establish a new connection: [Errno 111] Connection refused

During handling of the above exception, another exception occurred:

Traceback (most recent call last):
  File "/home/airflow/.local/lib/python3.8/site-packages/requests/adapters.py", line 486, in send
    resp = conn.urlopen(
  File "/home/airflow/.local/lib/python3.8/site-packages/urllib3/connectionpool.py", line 799, in urlopen
    retries = retries.increment(
  File "/home/airflow/.local/lib/python3.8/site-packages/urllib3/util/retry.py", line 592, in increment
    raise MaxRetryError(_pool, url, error or ResponseError(cause))
urllib3.exceptions.MaxRetryError: HTTPConnectionPool(host='localhost', port=8085): Max retries exceeded with url: /run_simulator (Caused by NewConnectionError('<urllib3.connection.HTTPConnection object at 0x7f7592721e50>: Failed to establish a new connection: [Errno 111] Connection refused'))

During handling of the above exception, another exception occurred:

Traceback (most recent call last):
  File "/home/airflow/.local/lib/python3.8/site-packages/airflow/operators/python.py", line 192, in execute
    return_value = self.execute_callable()
  File "/home/airflow/.local/lib/python3.8/site-packages/airflow/operators/python.py", line 209, in execute_callable
    return self.python_callable(*self.op_args, **self.op_kwargs)
  File "/opt/airflow/dags/timeseries.py", line 51, in setup_and_run_simulator
    trigger_run_simulator(simulator_data_dict, **kwargs)
  File "/opt/airflow/dags/timeseries.py", line 61, in trigger_run_simulator
    response = requests.post(api_endpoint, json={"id": simulator_data_dict["id"]})
  File "/home/airflow/.local/lib/python3.8/site-packages/requests/api.py", line 115, in post
    return request("post", url, data=data, json=json, **kwargs)
  File "/home/airflow/.local/lib/python3.8/site-packages/requests/api.py", line 59, in request
    return session.request(method=method, url=url, **kwargs)
  File "/home/airflow/.local/lib/python3.8/site-packages/requests/sessions.py", line 589, in request
    resp = self.send(prep, **send_kwargs)
  File "/home/airflow/.local/lib/python3.8/site-packages/requests/sessions.py", line 703, in send
    r = adapter.send(request, **kwargs)
  File "/home/airflow/.local/lib/python3.8/site-packages/requests/adapters.py", line 519, in send
    raise ConnectionError(e, request=request)
requests.exceptions.ConnectionError: HTTPConnectionPool(host='localhost', port=8085): Max retries exceeded with url: /run_simulator (Caused by NewConnectionError('<urllib3.connection.HTTPConnection object at 0x7f7592721e50>: Failed to establish a new connection: [Errno 111] Connection refused'))
[2023-11-12T14:01:37.655+0000] {taskinstance.py:1400} INFO - Marking task as FAILED. dag_id=simulator_dag_1, task_id=setup_and_run_simulator_task_1, execution_date=20231111T000000, start_date=20231112T140137, end_date=20231112T140137
[2023-11-12T14:01:37.691+0000] {standard_task_runner.py:104} ERROR - Failed to execute job 37 for task setup_and_run_simulator_task_1 (HTTPConnectionPool(host='localhost', port=8085): Max retries exceeded with url: /run_simulator (Caused by NewConnectionError('<urllib3.connection.HTTPConnection object at 0x7f7592721e50>: Failed to establish a new connection: [Errno 111] Connection refused')); 907)
[2023-11-12T14:01:37.734+0000] {local_task_job_runner.py:228} INFO - Task exited with return code 1
[2023-11-12T14:01:37.776+0000] {taskinstance.py:2778} INFO - 0 downstream tasks scheduled from follow-on schedule check
[2023-11-12T14:03:15.001+0000] {logging_mixin.py:154} INFO - Changing /opt/***/logs/dag_id=simulator_dag_1/run_id=scheduled__2023-11-11T00:00:00+00:00/task_id=setup_and_run_simulator_task_1 permission to 509
[2023-11-12T14:03:15.004+0000] {logging_mixin.py:154} INFO - Failed to change /opt/***/logs/dag_id=simulator_dag_1/run_id=scheduled__2023-11-11T00:00:00+00:00/task_id=setup_and_run_simulator_task_1 permission to 509: [Errno 1] Operation not permitted: '/opt/***/logs/dag_id=simulator_dag_1/run_id=scheduled__2023-11-11T00:00:00+00:00/task_id=setup_and_run_simulator_task_1'
[2023-11-12T14:03:15.055+0000] {logging_mixin.py:154} INFO - Changing /opt/***/logs/dag_id=simulator_dag_1/run_id=scheduled__2023-11-11T00:00:00+00:00/task_id=setup_and_run_simulator_task_1 permission to 509
[2023-11-12T14:03:15.057+0000] {logging_mixin.py:154} INFO - Failed to change /opt/***/logs/dag_id=simulator_dag_1/run_id=scheduled__2023-11-11T00:00:00+00:00/task_id=setup_and_run_simulator_task_1 permission to 509: [Errno 1] Operation not permitted: '/opt/***/logs/dag_id=simulator_dag_1/run_id=scheduled__2023-11-11T00:00:00+00:00/task_id=setup_and_run_simulator_task_1'
[2023-11-12T14:03:15.110+0000] {taskinstance.py:1159} INFO - Dependencies all met for dep_context=non-requeueable deps ti=<TaskInstance: simulator_dag_1.setup_and_run_simulator_task_1 scheduled__2023-11-11T00:00:00+00:00 [queued]>
[2023-11-12T14:03:15.124+0000] {taskinstance.py:1159} INFO - Dependencies all met for dep_context=requeueable deps ti=<TaskInstance: simulator_dag_1.setup_and_run_simulator_task_1 scheduled__2023-11-11T00:00:00+00:00 [queued]>
[2023-11-12T14:03:15.126+0000] {taskinstance.py:1361} INFO - Starting attempt 1 of 1
[2023-11-12T14:03:15.150+0000] {taskinstance.py:1382} INFO - Executing <Task(PythonOperator): setup_and_run_simulator_task_1> on 2023-11-11 00:00:00+00:00
[2023-11-12T14:03:15.346+0000] {standard_task_runner.py:57} INFO - Started process 929 to run task
[2023-11-12T14:03:15.356+0000] {standard_task_runner.py:84} INFO - Running: ['***', 'tasks', 'run', 'simulator_dag_1', 'setup_and_run_simulator_task_1', 'scheduled__2023-11-11T00:00:00+00:00', '--job-id', '39', '--raw', '--subdir', 'DAGS_FOLDER/timeseries.py', '--cfg-path', '/tmp/tmpgt_98iz5']
[2023-11-12T14:03:15.367+0000] {standard_task_runner.py:85} INFO - Job 39: Subtask setup_and_run_simulator_task_1
[2023-11-12T14:03:15.454+0000] {logging_mixin.py:154} INFO - Changing /opt/***/logs/dag_id=simulator_dag_1/run_id=scheduled__2023-11-11T00:00:00+00:00/task_id=setup_and_run_simulator_task_1 permission to 509
[2023-11-12T14:03:15.455+0000] {logging_mixin.py:154} INFO - Failed to change /opt/***/logs/dag_id=simulator_dag_1/run_id=scheduled__2023-11-11T00:00:00+00:00/task_id=setup_and_run_simulator_task_1 permission to 509: [Errno 1] Operation not permitted: '/opt/***/logs/dag_id=simulator_dag_1/run_id=scheduled__2023-11-11T00:00:00+00:00/task_id=setup_and_run_simulator_task_1'
[2023-11-12T14:03:15.463+0000] {task_command.py:416} INFO - Running <TaskInstance: simulator_dag_1.setup_and_run_simulator_task_1 scheduled__2023-11-11T00:00:00+00:00 [running]> on host 4bc8bf47bb6b
[2023-11-12T14:03:15.585+0000] {taskinstance.py:1662} INFO - Exporting env vars: AIRFLOW_CTX_DAG_OWNER='***' AIRFLOW_CTX_DAG_ID='simulator_dag_1' AIRFLOW_CTX_TASK_ID='setup_and_run_simulator_task_1' AIRFLOW_CTX_EXECUTION_DATE='2023-11-11T00:00:00+00:00' AIRFLOW_CTX_TRY_NUMBER='1' AIRFLOW_CTX_DAG_RUN_ID='scheduled__2023-11-11T00:00:00+00:00'
[2023-11-12T14:03:15.596+0000] {taskinstance.py:1937} ERROR - Task failed with exception
Traceback (most recent call last):
  File "/home/airflow/.local/lib/python3.8/site-packages/urllib3/connection.py", line 174, in _new_conn
    conn = connection.create_connection(
  File "/home/airflow/.local/lib/python3.8/site-packages/urllib3/util/connection.py", line 95, in create_connection
    raise err
  File "/home/airflow/.local/lib/python3.8/site-packages/urllib3/util/connection.py", line 85, in create_connection
    sock.connect(sa)
ConnectionRefusedError: [Errno 111] Connection refused

During handling of the above exception, another exception occurred:

Traceback (most recent call last):
  File "/home/airflow/.local/lib/python3.8/site-packages/urllib3/connectionpool.py", line 715, in urlopen
    httplib_response = self._make_request(
  File "/home/airflow/.local/lib/python3.8/site-packages/urllib3/connectionpool.py", line 416, in _make_request
    conn.request(method, url, **httplib_request_kw)
  File "/home/airflow/.local/lib/python3.8/site-packages/urllib3/connection.py", line 244, in request
    super(HTTPConnection, self).request(method, url, body=body, headers=headers)
  File "/usr/local/lib/python3.8/http/client.py", line 1256, in request
    self._send_request(method, url, body, headers, encode_chunked)
  File "/usr/local/lib/python3.8/http/client.py", line 1302, in _send_request
    self.endheaders(body, encode_chunked=encode_chunked)
  File "/usr/local/lib/python3.8/http/client.py", line 1251, in endheaders
    self._send_output(message_body, encode_chunked=encode_chunked)
  File "/usr/local/lib/python3.8/http/client.py", line 1011, in _send_output
    self.send(msg)
  File "/usr/local/lib/python3.8/http/client.py", line 951, in send
    self.connect()
  File "/home/airflow/.local/lib/python3.8/site-packages/urllib3/connection.py", line 205, in connect
    conn = self._new_conn()
  File "/home/airflow/.local/lib/python3.8/site-packages/urllib3/connection.py", line 186, in _new_conn
    raise NewConnectionError(
urllib3.exceptions.NewConnectionError: <urllib3.connection.HTTPConnection object at 0x7f7592721a60>: Failed to establish a new connection: [Errno 111] Connection refused

During handling of the above exception, another exception occurred:

Traceback (most recent call last):
  File "/home/airflow/.local/lib/python3.8/site-packages/requests/adapters.py", line 486, in send
    resp = conn.urlopen(
  File "/home/airflow/.local/lib/python3.8/site-packages/urllib3/connectionpool.py", line 799, in urlopen
    retries = retries.increment(
  File "/home/airflow/.local/lib/python3.8/site-packages/urllib3/util/retry.py", line 592, in increment
    raise MaxRetryError(_pool, url, error or ResponseError(cause))
urllib3.exceptions.MaxRetryError: HTTPConnectionPool(host='127.0.0.1', port=8085): Max retries exceeded with url: /run_simulator/ (Caused by NewConnectionError('<urllib3.connection.HTTPConnection object at 0x7f7592721a60>: Failed to establish a new connection: [Errno 111] Connection refused'))

During handling of the above exception, another exception occurred:

Traceback (most recent call last):
  File "/home/airflow/.local/lib/python3.8/site-packages/airflow/operators/python.py", line 192, in execute
    return_value = self.execute_callable()
  File "/home/airflow/.local/lib/python3.8/site-packages/airflow/operators/python.py", line 209, in execute_callable
    return self.python_callable(*self.op_args, **self.op_kwargs)
  File "/opt/airflow/dags/timeseries.py", line 51, in setup_and_run_simulator
    trigger_run_simulator(simulator_data_dict, **kwargs)
  File "/opt/airflow/dags/timeseries.py", line 61, in trigger_run_simulator
    response = requests.post(api_endpoint, json={"id": simulator_data_dict["id"]})
  File "/home/airflow/.local/lib/python3.8/site-packages/requests/api.py", line 115, in post
    return request("post", url, data=data, json=json, **kwargs)
  File "/home/airflow/.local/lib/python3.8/site-packages/requests/api.py", line 59, in request
    return session.request(method=method, url=url, **kwargs)
  File "/home/airflow/.local/lib/python3.8/site-packages/requests/sessions.py", line 589, in request
    resp = self.send(prep, **send_kwargs)
  File "/home/airflow/.local/lib/python3.8/site-packages/requests/sessions.py", line 703, in send
    r = adapter.send(request, **kwargs)
  File "/home/airflow/.local/lib/python3.8/site-packages/requests/adapters.py", line 519, in send
    raise ConnectionError(e, request=request)
requests.exceptions.ConnectionError: HTTPConnectionPool(host='127.0.0.1', port=8085): Max retries exceeded with url: /run_simulator/ (Caused by NewConnectionError('<urllib3.connection.HTTPConnection object at 0x7f7592721a60>: Failed to establish a new connection: [Errno 111] Connection refused'))
[2023-11-12T14:03:15.623+0000] {taskinstance.py:1400} INFO - Marking task as FAILED. dag_id=simulator_dag_1, task_id=setup_and_run_simulator_task_1, execution_date=20231111T000000, start_date=20231112T140315, end_date=20231112T140315
[2023-11-12T14:03:15.648+0000] {standard_task_runner.py:104} ERROR - Failed to execute job 39 for task setup_and_run_simulator_task_1 (HTTPConnectionPool(host='127.0.0.1', port=8085): Max retries exceeded with url: /run_simulator/ (Caused by NewConnectionError('<urllib3.connection.HTTPConnection object at 0x7f7592721a60>: Failed to establish a new connection: [Errno 111] Connection refused')); 929)
[2023-11-12T14:03:15.694+0000] {local_task_job_runner.py:228} INFO - Task exited with return code 1
[2023-11-12T14:03:15.721+0000] {taskinstance.py:2778} INFO - 0 downstream tasks scheduled from follow-on schedule check
[2023-11-12T15:35:47.962+0000] {logging_mixin.py:154} INFO - Changing /opt/***/logs/dag_id=simulator_dag_1/run_id=scheduled__2023-11-11T00:00:00+00:00/task_id=setup_and_run_simulator_task_1 permission to 509
[2023-11-12T15:35:47.963+0000] {logging_mixin.py:154} INFO - Failed to change /opt/***/logs/dag_id=simulator_dag_1/run_id=scheduled__2023-11-11T00:00:00+00:00/task_id=setup_and_run_simulator_task_1 permission to 509: [Errno 1] Operation not permitted: '/opt/***/logs/dag_id=simulator_dag_1/run_id=scheduled__2023-11-11T00:00:00+00:00/task_id=setup_and_run_simulator_task_1'
[2023-11-12T15:35:48.003+0000] {logging_mixin.py:154} INFO - Changing /opt/***/logs/dag_id=simulator_dag_1/run_id=scheduled__2023-11-11T00:00:00+00:00/task_id=setup_and_run_simulator_task_1 permission to 509
[2023-11-12T15:35:48.004+0000] {logging_mixin.py:154} INFO - Failed to change /opt/***/logs/dag_id=simulator_dag_1/run_id=scheduled__2023-11-11T00:00:00+00:00/task_id=setup_and_run_simulator_task_1 permission to 509: [Errno 1] Operation not permitted: '/opt/***/logs/dag_id=simulator_dag_1/run_id=scheduled__2023-11-11T00:00:00+00:00/task_id=setup_and_run_simulator_task_1'
[2023-11-12T15:35:48.049+0000] {taskinstance.py:1159} INFO - Dependencies all met for dep_context=non-requeueable deps ti=<TaskInstance: simulator_dag_1.setup_and_run_simulator_task_1 scheduled__2023-11-11T00:00:00+00:00 [queued]>
[2023-11-12T15:35:48.061+0000] {taskinstance.py:1159} INFO - Dependencies all met for dep_context=requeueable deps ti=<TaskInstance: simulator_dag_1.setup_and_run_simulator_task_1 scheduled__2023-11-11T00:00:00+00:00 [queued]>
[2023-11-12T15:35:48.062+0000] {taskinstance.py:1361} INFO - Starting attempt 1 of 3
[2023-11-12T15:35:48.079+0000] {taskinstance.py:1382} INFO - Executing <Task(PythonOperator): setup_and_run_simulator_task_1> on 2023-11-11 00:00:00+00:00
[2023-11-12T15:35:48.085+0000] {standard_task_runner.py:57} INFO - Started process 619 to run task
[2023-11-12T15:35:48.090+0000] {standard_task_runner.py:84} INFO - Running: ['***', 'tasks', 'run', 'simulator_dag_1', 'setup_and_run_simulator_task_1', 'scheduled__2023-11-11T00:00:00+00:00', '--job-id', '3', '--raw', '--subdir', 'DAGS_FOLDER/timeseries.py', '--cfg-path', '/tmp/tmprxr0q7_4']
[2023-11-12T15:35:48.094+0000] {standard_task_runner.py:85} INFO - Job 3: Subtask setup_and_run_simulator_task_1
[2023-11-12T15:35:48.285+0000] {logging_mixin.py:154} INFO - Changing /opt/***/logs/dag_id=simulator_dag_1/run_id=scheduled__2023-11-11T00:00:00+00:00/task_id=setup_and_run_simulator_task_1 permission to 509
[2023-11-12T15:35:48.287+0000] {logging_mixin.py:154} INFO - Failed to change /opt/***/logs/dag_id=simulator_dag_1/run_id=scheduled__2023-11-11T00:00:00+00:00/task_id=setup_and_run_simulator_task_1 permission to 509: [Errno 1] Operation not permitted: '/opt/***/logs/dag_id=simulator_dag_1/run_id=scheduled__2023-11-11T00:00:00+00:00/task_id=setup_and_run_simulator_task_1'
[2023-11-12T15:35:48.292+0000] {task_command.py:416} INFO - Running <TaskInstance: simulator_dag_1.setup_and_run_simulator_task_1 scheduled__2023-11-11T00:00:00+00:00 [running]> on host e15777c5c324
[2023-11-12T15:35:48.380+0000] {taskinstance.py:1662} INFO - Exporting env vars: AIRFLOW_CTX_DAG_OWNER='***' AIRFLOW_CTX_DAG_ID='simulator_dag_1' AIRFLOW_CTX_TASK_ID='setup_and_run_simulator_task_1' AIRFLOW_CTX_EXECUTION_DATE='2023-11-11T00:00:00+00:00' AIRFLOW_CTX_TRY_NUMBER='1' AIRFLOW_CTX_DAG_RUN_ID='scheduled__2023-11-11T00:00:00+00:00'
[2023-11-12T15:35:48.383+0000] {taskinstance.py:1937} ERROR - Task failed with exception
Traceback (most recent call last):
  File "/home/airflow/.local/lib/python3.8/site-packages/airflow/operators/python.py", line 192, in execute
    return_value = self.execute_callable()
  File "/home/airflow/.local/lib/python3.8/site-packages/airflow/operators/python.py", line 209, in execute_callable
    return self.python_callable(*self.op_args, **self.op_kwargs)
  File "/opt/airflow/dags/timeseries.py", line 54, in setup_and_run_simulator
    trigger_run_simulator(simulator_data_dict, **kwargs)
  File "/opt/airflow/dags/timeseries.py", line 59, in trigger_run_simulator
    run_simulator({"id": simulator_data_dict["id"]})
  File "/home/airflow/.local/lib/python3.8/site-packages/django/views/decorators/csrf.py", line 56, in wrapper_view
    return view_func(*args, **kwargs)
  File "/home/airflow/.local/lib/python3.8/site-packages/django/views/generic/base.py", line 104, in view
    return self.dispatch(request, *args, **kwargs)
  File "/home/airflow/.local/lib/python3.8/site-packages/rest_framework/views.py", line 492, in dispatch
    request = self.initialize_request(request, *args, **kwargs)
  File "/home/airflow/.local/lib/python3.8/site-packages/rest_framework/views.py", line 391, in initialize_request
    return Request(
  File "/home/airflow/.local/lib/python3.8/site-packages/rest_framework/request.py", line 154, in __init__
    assert isinstance(request, HttpRequest), (
AssertionError: The `request` argument must be an instance of `django.http.HttpRequest`, not `builtins.dict`.
[2023-11-12T15:35:48.400+0000] {taskinstance.py:1400} INFO - Marking task as UP_FOR_RETRY. dag_id=simulator_dag_1, task_id=setup_and_run_simulator_task_1, execution_date=20231111T000000, start_date=20231112T153548, end_date=20231112T153548
[2023-11-12T15:35:48.414+0000] {standard_task_runner.py:104} ERROR - Failed to execute job 3 for task setup_and_run_simulator_task_1 (The `request` argument must be an instance of `django.http.HttpRequest`, not `builtins.dict`.; 619)
[2023-11-12T15:35:48.469+0000] {local_task_job_runner.py:228} INFO - Task exited with return code 1
[2023-11-12T15:35:48.489+0000] {taskinstance.py:2778} INFO - 0 downstream tasks scheduled from follow-on schedule check
[2023-11-12T16:01:40.169+0000] {logging_mixin.py:154} INFO - Changing /opt/***/logs/dag_id=simulator_dag_1/run_id=scheduled__2023-11-11T00:00:00+00:00/task_id=setup_and_run_simulator_task_1 permission to 509
[2023-11-12T16:01:40.173+0000] {logging_mixin.py:154} INFO - Failed to change /opt/***/logs/dag_id=simulator_dag_1/run_id=scheduled__2023-11-11T00:00:00+00:00/task_id=setup_and_run_simulator_task_1 permission to 509: [Errno 1] Operation not permitted: '/opt/***/logs/dag_id=simulator_dag_1/run_id=scheduled__2023-11-11T00:00:00+00:00/task_id=setup_and_run_simulator_task_1'
[2023-11-12T16:01:40.473+0000] {logging_mixin.py:154} INFO - Changing /opt/***/logs/dag_id=simulator_dag_1/run_id=scheduled__2023-11-11T00:00:00+00:00/task_id=setup_and_run_simulator_task_1 permission to 509
[2023-11-12T16:01:40.489+0000] {logging_mixin.py:154} INFO - Failed to change /opt/***/logs/dag_id=simulator_dag_1/run_id=scheduled__2023-11-11T00:00:00+00:00/task_id=setup_and_run_simulator_task_1 permission to 509: [Errno 1] Operation not permitted: '/opt/***/logs/dag_id=simulator_dag_1/run_id=scheduled__2023-11-11T00:00:00+00:00/task_id=setup_and_run_simulator_task_1'
[2023-11-12T16:01:40.700+0000] {taskinstance.py:1159} INFO - Dependencies all met for dep_context=non-requeueable deps ti=<TaskInstance: simulator_dag_1.setup_and_run_simulator_task_1 scheduled__2023-11-11T00:00:00+00:00 [queued]>
[2023-11-12T16:01:40.785+0000] {taskinstance.py:1159} INFO - Dependencies all met for dep_context=requeueable deps ti=<TaskInstance: simulator_dag_1.setup_and_run_simulator_task_1 scheduled__2023-11-11T00:00:00+00:00 [queued]>
[2023-11-12T16:01:40.807+0000] {taskinstance.py:1361} INFO - Starting attempt 1 of 3
[2023-11-12T16:01:41.085+0000] {taskinstance.py:1382} INFO - Executing <Task(PythonOperator): setup_and_run_simulator_task_1> on 2023-11-11 00:00:00+00:00
[2023-11-12T16:01:41.290+0000] {standard_task_runner.py:57} INFO - Started process 997 to run task
[2023-11-12T16:01:41.327+0000] {standard_task_runner.py:84} INFO - Running: ['***', 'tasks', 'run', 'simulator_dag_1', 'setup_and_run_simulator_task_1', 'scheduled__2023-11-11T00:00:00+00:00', '--job-id', '6', '--raw', '--subdir', 'DAGS_FOLDER/timeseries.py', '--cfg-path', '/tmp/tmpcq5s_xf_']
[2023-11-12T16:01:41.399+0000] {standard_task_runner.py:85} INFO - Job 6: Subtask setup_and_run_simulator_task_1
[2023-11-12T16:01:41.870+0000] {logging_mixin.py:154} INFO - Changing /opt/***/logs/dag_id=simulator_dag_1/run_id=scheduled__2023-11-11T00:00:00+00:00/task_id=setup_and_run_simulator_task_1 permission to 509
[2023-11-12T16:01:41.880+0000] {logging_mixin.py:154} INFO - Failed to change /opt/***/logs/dag_id=simulator_dag_1/run_id=scheduled__2023-11-11T00:00:00+00:00/task_id=setup_and_run_simulator_task_1 permission to 509: [Errno 1] Operation not permitted: '/opt/***/logs/dag_id=simulator_dag_1/run_id=scheduled__2023-11-11T00:00:00+00:00/task_id=setup_and_run_simulator_task_1'
[2023-11-12T16:01:41.942+0000] {task_command.py:416} INFO - Running <TaskInstance: simulator_dag_1.setup_and_run_simulator_task_1 scheduled__2023-11-11T00:00:00+00:00 [running]> on host e15777c5c324
[2023-11-12T16:01:42.611+0000] {taskinstance.py:1662} INFO - Exporting env vars: AIRFLOW_CTX_DAG_OWNER='***' AIRFLOW_CTX_DAG_ID='simulator_dag_1' AIRFLOW_CTX_TASK_ID='setup_and_run_simulator_task_1' AIRFLOW_CTX_EXECUTION_DATE='2023-11-11T00:00:00+00:00' AIRFLOW_CTX_TRY_NUMBER='1' AIRFLOW_CTX_DAG_RUN_ID='scheduled__2023-11-11T00:00:00+00:00'
[2023-11-12T16:01:42.655+0000] {python.py:194} INFO - Done. Returned value was: None
[2023-11-12T16:01:42.695+0000] {taskinstance.py:1400} INFO - Marking task as SUCCESS. dag_id=simulator_dag_1, task_id=setup_and_run_simulator_task_1, execution_date=20231111T000000, start_date=20231112T160140, end_date=20231112T160142
[2023-11-12T16:01:42.824+0000] {local_task_job_runner.py:228} INFO - Task exited with return code 0
[2023-11-12T16:01:42.931+0000] {taskinstance.py:2778} INFO - 0 downstream tasks scheduled from follow-on schedule check
[2023-11-12T16:12:43.467+0000] {logging_mixin.py:154} INFO - Changing /opt/***/logs/dag_id=simulator_dag_1/run_id=scheduled__2023-11-11T00:00:00+00:00/task_id=setup_and_run_simulator_task_1 permission to 509
[2023-11-12T16:12:43.489+0000] {logging_mixin.py:154} INFO - Failed to change /opt/***/logs/dag_id=simulator_dag_1/run_id=scheduled__2023-11-11T00:00:00+00:00/task_id=setup_and_run_simulator_task_1 permission to 509: [Errno 1] Operation not permitted: '/opt/***/logs/dag_id=simulator_dag_1/run_id=scheduled__2023-11-11T00:00:00+00:00/task_id=setup_and_run_simulator_task_1'
[2023-11-12T16:12:43.653+0000] {logging_mixin.py:154} INFO - Changing /opt/***/logs/dag_id=simulator_dag_1/run_id=scheduled__2023-11-11T00:00:00+00:00/task_id=setup_and_run_simulator_task_1 permission to 509
[2023-11-12T16:12:43.656+0000] {logging_mixin.py:154} INFO - Failed to change /opt/***/logs/dag_id=simulator_dag_1/run_id=scheduled__2023-11-11T00:00:00+00:00/task_id=setup_and_run_simulator_task_1 permission to 509: [Errno 1] Operation not permitted: '/opt/***/logs/dag_id=simulator_dag_1/run_id=scheduled__2023-11-11T00:00:00+00:00/task_id=setup_and_run_simulator_task_1'
[2023-11-12T16:12:43.880+0000] {taskinstance.py:1159} INFO - Dependencies all met for dep_context=non-requeueable deps ti=<TaskInstance: simulator_dag_1.setup_and_run_simulator_task_1 scheduled__2023-11-11T00:00:00+00:00 [queued]>
[2023-11-12T16:12:43.938+0000] {taskinstance.py:1159} INFO - Dependencies all met for dep_context=requeueable deps ti=<TaskInstance: simulator_dag_1.setup_and_run_simulator_task_1 scheduled__2023-11-11T00:00:00+00:00 [queued]>
[2023-11-12T16:12:43.950+0000] {taskinstance.py:1361} INFO - Starting attempt 1 of 3
[2023-11-12T16:12:44.025+0000] {taskinstance.py:1382} INFO - Executing <Task(PythonOperator): setup_and_run_simulator_task_1> on 2023-11-11 00:00:00+00:00
[2023-11-12T16:12:44.048+0000] {standard_task_runner.py:57} INFO - Started process 1149 to run task
[2023-11-12T16:12:44.082+0000] {standard_task_runner.py:84} INFO - Running: ['***', 'tasks', 'run', 'simulator_dag_1', 'setup_and_run_simulator_task_1', 'scheduled__2023-11-11T00:00:00+00:00', '--job-id', '10', '--raw', '--subdir', 'DAGS_FOLDER/timeseries.py', '--cfg-path', '/tmp/tmpednh2fpj']
[2023-11-12T16:12:44.103+0000] {standard_task_runner.py:85} INFO - Job 10: Subtask setup_and_run_simulator_task_1
[2023-11-12T16:12:44.564+0000] {logging_mixin.py:154} INFO - Changing /opt/***/logs/dag_id=simulator_dag_1/run_id=scheduled__2023-11-11T00:00:00+00:00/task_id=setup_and_run_simulator_task_1 permission to 509
[2023-11-12T16:12:44.572+0000] {logging_mixin.py:154} INFO - Failed to change /opt/***/logs/dag_id=simulator_dag_1/run_id=scheduled__2023-11-11T00:00:00+00:00/task_id=setup_and_run_simulator_task_1 permission to 509: [Errno 1] Operation not permitted: '/opt/***/logs/dag_id=simulator_dag_1/run_id=scheduled__2023-11-11T00:00:00+00:00/task_id=setup_and_run_simulator_task_1'
[2023-11-12T16:12:44.634+0000] {task_command.py:416} INFO - Running <TaskInstance: simulator_dag_1.setup_and_run_simulator_task_1 scheduled__2023-11-11T00:00:00+00:00 [running]> on host e15777c5c324
[2023-11-12T16:12:45.300+0000] {taskinstance.py:1662} INFO - Exporting env vars: AIRFLOW_CTX_DAG_OWNER='***' AIRFLOW_CTX_DAG_ID='simulator_dag_1' AIRFLOW_CTX_TASK_ID='setup_and_run_simulator_task_1' AIRFLOW_CTX_EXECUTION_DATE='2023-11-11T00:00:00+00:00' AIRFLOW_CTX_TRY_NUMBER='1' AIRFLOW_CTX_DAG_RUN_ID='scheduled__2023-11-11T00:00:00+00:00'
[2023-11-12T16:12:45.338+0000] {taskinstance.py:1937} ERROR - Task failed with exception
Traceback (most recent call last):
  File "/home/airflow/.local/lib/python3.8/site-packages/urllib3/connection.py", line 174, in _new_conn
    conn = connection.create_connection(
  File "/home/airflow/.local/lib/python3.8/site-packages/urllib3/util/connection.py", line 95, in create_connection
    raise err
  File "/home/airflow/.local/lib/python3.8/site-packages/urllib3/util/connection.py", line 85, in create_connection
    sock.connect(sa)
ConnectionRefusedError: [Errno 111] Connection refused

During handling of the above exception, another exception occurred:

Traceback (most recent call last):
  File "/home/airflow/.local/lib/python3.8/site-packages/urllib3/connectionpool.py", line 715, in urlopen
    httplib_response = self._make_request(
  File "/home/airflow/.local/lib/python3.8/site-packages/urllib3/connectionpool.py", line 416, in _make_request
    conn.request(method, url, **httplib_request_kw)
  File "/home/airflow/.local/lib/python3.8/site-packages/urllib3/connection.py", line 244, in request
    super(HTTPConnection, self).request(method, url, body=body, headers=headers)
  File "/usr/local/lib/python3.8/http/client.py", line 1256, in request
    self._send_request(method, url, body, headers, encode_chunked)
  File "/usr/local/lib/python3.8/http/client.py", line 1302, in _send_request
    self.endheaders(body, encode_chunked=encode_chunked)
  File "/usr/local/lib/python3.8/http/client.py", line 1251, in endheaders
    self._send_output(message_body, encode_chunked=encode_chunked)
  File "/usr/local/lib/python3.8/http/client.py", line 1011, in _send_output
    self.send(msg)
  File "/usr/local/lib/python3.8/http/client.py", line 951, in send
    self.connect()
  File "/home/airflow/.local/lib/python3.8/site-packages/urllib3/connection.py", line 205, in connect
    conn = self._new_conn()
  File "/home/airflow/.local/lib/python3.8/site-packages/urllib3/connection.py", line 186, in _new_conn
    raise NewConnectionError(
urllib3.exceptions.NewConnectionError: <urllib3.connection.HTTPConnection object at 0x7fcced6a0970>: Failed to establish a new connection: [Errno 111] Connection refused

During handling of the above exception, another exception occurred:

Traceback (most recent call last):
  File "/home/airflow/.local/lib/python3.8/site-packages/requests/adapters.py", line 486, in send
    resp = conn.urlopen(
  File "/home/airflow/.local/lib/python3.8/site-packages/urllib3/connectionpool.py", line 799, in urlopen
    retries = retries.increment(
  File "/home/airflow/.local/lib/python3.8/site-packages/urllib3/util/retry.py", line 592, in increment
    raise MaxRetryError(_pool, url, error or ResponseError(cause))
urllib3.exceptions.MaxRetryError: HTTPConnectionPool(host='localhost', port=8085): Max retries exceeded with url: /run_simulator/ (Caused by NewConnectionError('<urllib3.connection.HTTPConnection object at 0x7fcced6a0970>: Failed to establish a new connection: [Errno 111] Connection refused'))

During handling of the above exception, another exception occurred:

Traceback (most recent call last):
  File "/home/airflow/.local/lib/python3.8/site-packages/airflow/operators/python.py", line 192, in execute
    return_value = self.execute_callable()
  File "/home/airflow/.local/lib/python3.8/site-packages/airflow/operators/python.py", line 209, in execute_callable
    return self.python_callable(*self.op_args, **self.op_kwargs)
  File "/opt/airflow/dags/timeseries.py", line 53, in setup_and_run_simulator
    trigger_run_simulator(simulator_data_dict, **kwargs)
  File "/opt/airflow/dags/timeseries.py", line 61, in trigger_run_simulator
    response = requests.post(api_endpoint, data={"id": simulator_id})
  File "/home/airflow/.local/lib/python3.8/site-packages/requests/api.py", line 115, in post
    return request("post", url, data=data, json=json, **kwargs)
  File "/home/airflow/.local/lib/python3.8/site-packages/requests/api.py", line 59, in request
    return session.request(method=method, url=url, **kwargs)
  File "/home/airflow/.local/lib/python3.8/site-packages/requests/sessions.py", line 589, in request
    resp = self.send(prep, **send_kwargs)
  File "/home/airflow/.local/lib/python3.8/site-packages/requests/sessions.py", line 703, in send
    r = adapter.send(request, **kwargs)
  File "/home/airflow/.local/lib/python3.8/site-packages/requests/adapters.py", line 519, in send
    raise ConnectionError(e, request=request)
requests.exceptions.ConnectionError: HTTPConnectionPool(host='localhost', port=8085): Max retries exceeded with url: /run_simulator/ (Caused by NewConnectionError('<urllib3.connection.HTTPConnection object at 0x7fcced6a0970>: Failed to establish a new connection: [Errno 111] Connection refused'))
[2023-11-12T16:12:45.458+0000] {taskinstance.py:1400} INFO - Marking task as UP_FOR_RETRY. dag_id=simulator_dag_1, task_id=setup_and_run_simulator_task_1, execution_date=20231111T000000, start_date=20231112T161243, end_date=20231112T161245
[2023-11-12T16:12:45.526+0000] {standard_task_runner.py:104} ERROR - Failed to execute job 10 for task setup_and_run_simulator_task_1 (HTTPConnectionPool(host='localhost', port=8085): Max retries exceeded with url: /run_simulator/ (Caused by NewConnectionError('<urllib3.connection.HTTPConnection object at 0x7fcced6a0970>: Failed to establish a new connection: [Errno 111] Connection refused')); 1149)
[2023-11-12T16:12:45.597+0000] {local_task_job_runner.py:228} INFO - Task exited with return code 1
[2023-11-12T16:12:45.759+0000] {taskinstance.py:2778} INFO - 0 downstream tasks scheduled from follow-on schedule check
[2023-11-12T16:19:11.445+0000] {logging_mixin.py:154} INFO - Changing /opt/***/logs/dag_id=simulator_dag_1/run_id=scheduled__2023-11-11T00:00:00+00:00/task_id=setup_and_run_simulator_task_1 permission to 509
[2023-11-12T16:19:11.449+0000] {logging_mixin.py:154} INFO - Failed to change /opt/***/logs/dag_id=simulator_dag_1/run_id=scheduled__2023-11-11T00:00:00+00:00/task_id=setup_and_run_simulator_task_1 permission to 509: [Errno 1] Operation not permitted: '/opt/***/logs/dag_id=simulator_dag_1/run_id=scheduled__2023-11-11T00:00:00+00:00/task_id=setup_and_run_simulator_task_1'
[2023-11-12T16:19:11.513+0000] {logging_mixin.py:154} INFO - Changing /opt/***/logs/dag_id=simulator_dag_1/run_id=scheduled__2023-11-11T00:00:00+00:00/task_id=setup_and_run_simulator_task_1 permission to 509
[2023-11-12T16:19:11.515+0000] {logging_mixin.py:154} INFO - Failed to change /opt/***/logs/dag_id=simulator_dag_1/run_id=scheduled__2023-11-11T00:00:00+00:00/task_id=setup_and_run_simulator_task_1 permission to 509: [Errno 1] Operation not permitted: '/opt/***/logs/dag_id=simulator_dag_1/run_id=scheduled__2023-11-11T00:00:00+00:00/task_id=setup_and_run_simulator_task_1'
[2023-11-12T16:19:11.586+0000] {taskinstance.py:1159} INFO - Dependencies all met for dep_context=non-requeueable deps ti=<TaskInstance: simulator_dag_1.setup_and_run_simulator_task_1 scheduled__2023-11-11T00:00:00+00:00 [queued]>
[2023-11-12T16:19:11.607+0000] {taskinstance.py:1159} INFO - Dependencies all met for dep_context=requeueable deps ti=<TaskInstance: simulator_dag_1.setup_and_run_simulator_task_1 scheduled__2023-11-11T00:00:00+00:00 [queued]>
[2023-11-12T16:19:11.609+0000] {taskinstance.py:1361} INFO - Starting attempt 1 of 3
[2023-11-12T16:19:11.645+0000] {taskinstance.py:1382} INFO - Executing <Task(PythonOperator): setup_and_run_simulator_task_1> on 2023-11-11 00:00:00+00:00
[2023-11-12T16:19:11.659+0000] {standard_task_runner.py:57} INFO - Started process 1245 to run task
[2023-11-12T16:19:11.667+0000] {standard_task_runner.py:84} INFO - Running: ['***', 'tasks', 'run', 'simulator_dag_1', 'setup_and_run_simulator_task_1', 'scheduled__2023-11-11T00:00:00+00:00', '--job-id', '13', '--raw', '--subdir', 'DAGS_FOLDER/timeseries.py', '--cfg-path', '/tmp/tmp161xy1i3']
[2023-11-12T16:19:11.676+0000] {standard_task_runner.py:85} INFO - Job 13: Subtask setup_and_run_simulator_task_1
[2023-11-12T16:19:11.769+0000] {logging_mixin.py:154} INFO - Changing /opt/***/logs/dag_id=simulator_dag_1/run_id=scheduled__2023-11-11T00:00:00+00:00/task_id=setup_and_run_simulator_task_1 permission to 509
[2023-11-12T16:19:11.773+0000] {logging_mixin.py:154} INFO - Failed to change /opt/***/logs/dag_id=simulator_dag_1/run_id=scheduled__2023-11-11T00:00:00+00:00/task_id=setup_and_run_simulator_task_1 permission to 509: [Errno 1] Operation not permitted: '/opt/***/logs/dag_id=simulator_dag_1/run_id=scheduled__2023-11-11T00:00:00+00:00/task_id=setup_and_run_simulator_task_1'
[2023-11-12T16:19:11.786+0000] {task_command.py:416} INFO - Running <TaskInstance: simulator_dag_1.setup_and_run_simulator_task_1 scheduled__2023-11-11T00:00:00+00:00 [running]> on host e15777c5c324
[2023-11-12T16:19:12.006+0000] {taskinstance.py:1662} INFO - Exporting env vars: AIRFLOW_CTX_DAG_OWNER='***' AIRFLOW_CTX_DAG_ID='simulator_dag_1' AIRFLOW_CTX_TASK_ID='setup_and_run_simulator_task_1' AIRFLOW_CTX_EXECUTION_DATE='2023-11-11T00:00:00+00:00' AIRFLOW_CTX_TRY_NUMBER='1' AIRFLOW_CTX_DAG_RUN_ID='scheduled__2023-11-11T00:00:00+00:00'
[2023-11-12T16:19:12.060+0000] {python.py:194} INFO - Done. Returned value was: None
[2023-11-12T16:19:12.116+0000] {taskinstance.py:1400} INFO - Marking task as SUCCESS. dag_id=simulator_dag_1, task_id=setup_and_run_simulator_task_1, execution_date=20231111T000000, start_date=20231112T161911, end_date=20231112T161912
[2023-11-12T16:19:12.234+0000] {local_task_job_runner.py:228} INFO - Task exited with return code 0
[2023-11-12T16:19:12.275+0000] {taskinstance.py:2778} INFO - 0 downstream tasks scheduled from follow-on schedule check
