[2023-11-12T19:49:28.207+0000] {logging_mixin.py:154} INFO - Changing /opt/***/logs/dag_id=simulator_dag_6/run_id=scheduled__2023-11-11T00:00:00+00:00/task_id=setup_and_run_simulator_task_6 permission to 509
[2023-11-12T19:49:28.212+0000] {logging_mixin.py:154} INFO - Failed to change /opt/***/logs/dag_id=simulator_dag_6/run_id=scheduled__2023-11-11T00:00:00+00:00/task_id=setup_and_run_simulator_task_6 permission to 509: [Errno 1] Operation not permitted: '/opt/***/logs/dag_id=simulator_dag_6/run_id=scheduled__2023-11-11T00:00:00+00:00/task_id=setup_and_run_simulator_task_6'
[2023-11-12T19:49:28.306+0000] {logging_mixin.py:154} INFO - Changing /opt/***/logs/dag_id=simulator_dag_6/run_id=scheduled__2023-11-11T00:00:00+00:00/task_id=setup_and_run_simulator_task_6 permission to 509
[2023-11-12T19:49:28.309+0000] {logging_mixin.py:154} INFO - Failed to change /opt/***/logs/dag_id=simulator_dag_6/run_id=scheduled__2023-11-11T00:00:00+00:00/task_id=setup_and_run_simulator_task_6 permission to 509: [Errno 1] Operation not permitted: '/opt/***/logs/dag_id=simulator_dag_6/run_id=scheduled__2023-11-11T00:00:00+00:00/task_id=setup_and_run_simulator_task_6'
[2023-11-12T19:49:28.470+0000] {taskinstance.py:1159} INFO - Dependencies all met for dep_context=non-requeueable deps ti=<TaskInstance: simulator_dag_6.setup_and_run_simulator_task_6 scheduled__2023-11-11T00:00:00+00:00 [queued]>
[2023-11-12T19:49:28.511+0000] {taskinstance.py:1159} INFO - Dependencies all met for dep_context=requeueable deps ti=<TaskInstance: simulator_dag_6.setup_and_run_simulator_task_6 scheduled__2023-11-11T00:00:00+00:00 [queued]>
[2023-11-12T19:49:28.515+0000] {taskinstance.py:1361} INFO - Starting attempt 1 of 3
[2023-11-12T19:49:28.587+0000] {taskinstance.py:1382} INFO - Executing <Task(PythonOperator): setup_and_run_simulator_task_6> on 2023-11-11 00:00:00+00:00
[2023-11-12T19:49:28.609+0000] {standard_task_runner.py:57} INFO - Started process 2025 to run task
[2023-11-12T19:49:28.628+0000] {standard_task_runner.py:84} INFO - Running: ['***', 'tasks', 'run', 'simulator_dag_6', 'setup_and_run_simulator_task_6', 'scheduled__2023-11-11T00:00:00+00:00', '--job-id', '22', '--raw', '--subdir', 'DAGS_FOLDER/timeseries.py', '--cfg-path', '/tmp/tmpfi3c_bif']
[2023-11-12T19:49:28.641+0000] {standard_task_runner.py:85} INFO - Job 22: Subtask setup_and_run_simulator_task_6
[2023-11-12T19:49:28.871+0000] {logging_mixin.py:154} INFO - Changing /opt/***/logs/dag_id=simulator_dag_6/run_id=scheduled__2023-11-11T00:00:00+00:00/task_id=setup_and_run_simulator_task_6 permission to 509
[2023-11-12T19:49:28.873+0000] {logging_mixin.py:154} INFO - Failed to change /opt/***/logs/dag_id=simulator_dag_6/run_id=scheduled__2023-11-11T00:00:00+00:00/task_id=setup_and_run_simulator_task_6 permission to 509: [Errno 1] Operation not permitted: '/opt/***/logs/dag_id=simulator_dag_6/run_id=scheduled__2023-11-11T00:00:00+00:00/task_id=setup_and_run_simulator_task_6'
[2023-11-12T19:49:28.893+0000] {task_command.py:416} INFO - Running <TaskInstance: simulator_dag_6.setup_and_run_simulator_task_6 scheduled__2023-11-11T00:00:00+00:00 [running]> on host e15777c5c324
[2023-11-12T19:49:29.456+0000] {taskinstance.py:1662} INFO - Exporting env vars: AIRFLOW_CTX_DAG_OWNER='***' AIRFLOW_CTX_DAG_ID='simulator_dag_6' AIRFLOW_CTX_TASK_ID='setup_and_run_simulator_task_6' AIRFLOW_CTX_EXECUTION_DATE='2023-11-11T00:00:00+00:00' AIRFLOW_CTX_TRY_NUMBER='1' AIRFLOW_CTX_DAG_RUN_ID='scheduled__2023-11-11T00:00:00+00:00'
[2023-11-12T19:49:29.472+0000] {taskinstance.py:1937} ERROR - Task failed with exception
Traceback (most recent call last):
  File "/home/airflow/.local/lib/python3.8/site-packages/airflow/operators/python.py", line 192, in execute
    return_value = self.execute_callable()
  File "/home/airflow/.local/lib/python3.8/site-packages/airflow/operators/python.py", line 209, in execute_callable
    return self.python_callable(*self.op_args, **self.op_kwargs)
  File "/opt/airflow/dags/timeseries.py", line 55, in setup_and_run_simulator
    os.chdir(working_directory)
FileNotFoundError: [Errno 2] No such file or directory: './djangoapp/Task1/main.py'
[2023-11-12T19:49:29.590+0000] {taskinstance.py:1400} INFO - Marking task as UP_FOR_RETRY. dag_id=simulator_dag_6, task_id=setup_and_run_simulator_task_6, execution_date=20231111T000000, start_date=20231112T194928, end_date=20231112T194929
[2023-11-12T19:49:29.661+0000] {standard_task_runner.py:104} ERROR - Failed to execute job 22 for task setup_and_run_simulator_task_6 ([Errno 2] No such file or directory: './djangoapp/Task1/main.py'; 2025)
[2023-11-12T19:49:29.760+0000] {local_task_job_runner.py:228} INFO - Task exited with return code 1
[2023-11-12T19:49:29.856+0000] {taskinstance.py:2778} INFO - 0 downstream tasks scheduled from follow-on schedule check
